[2021-06-30 08:51:53,862] {taskinstance.py:876} INFO - Dependencies all met for <TaskInstance: open_aq.process_data 2021-06-29T17:09:19.209771+00:00 [queued]>
[2021-06-30 08:51:53,901] {taskinstance.py:876} INFO - Dependencies all met for <TaskInstance: open_aq.process_data 2021-06-29T17:09:19.209771+00:00 [queued]>
[2021-06-30 08:51:53,903] {taskinstance.py:1067} INFO - 
--------------------------------------------------------------------------------
[2021-06-30 08:51:53,905] {taskinstance.py:1068} INFO - Starting attempt 7 of 7
[2021-06-30 08:51:53,907] {taskinstance.py:1069} INFO - 
--------------------------------------------------------------------------------
[2021-06-30 08:51:53,929] {taskinstance.py:1087} INFO - Executing <Task(PythonOperator): process_data> on 2021-06-29T17:09:19.209771+00:00
[2021-06-30 08:51:53,947] {standard_task_runner.py:52} INFO - Started process 7370 to run task
[2021-06-30 08:51:53,961] {standard_task_runner.py:76} INFO - Running: ['airflow', 'tasks', 'run', 'open_aq', 'process_data', '2021-06-29T17:09:19.209771+00:00', '--job-id', '775', '--pool', 'default_pool', '--raw', '--subdir', 'DAGS_FOLDER/open_aq.py', '--cfg-path', '/tmp/tmpm5v1ln1b', '--error-file', '/tmp/tmp1md4qfll']
[2021-06-30 08:51:53,962] {standard_task_runner.py:77} INFO - Job 775: Subtask process_data
[2021-06-30 08:51:54,094] {logging_mixin.py:104} INFO - Running <TaskInstance: open_aq.process_data 2021-06-29T17:09:19.209771+00:00 [running]> on host airflowvm
[2021-06-30 08:51:54,227] {taskinstance.py:1280} INFO - Exporting the following env vars:
AIRFLOW_CTX_DAG_OWNER=airflow
AIRFLOW_CTX_DAG_ID=open_aq
AIRFLOW_CTX_TASK_ID=process_data
AIRFLOW_CTX_EXECUTION_DATE=2021-06-29T17:09:19.209771+00:00
AIRFLOW_CTX_DAG_RUN_ID=manual__2021-06-29T17:09:19.209771+00:00
[2021-06-30 08:51:54,240] {taskinstance.py:1481} ERROR - Task failed with exception
Traceback (most recent call last):
  File "/home/airflow/sandbox/lib/python3.8/site-packages/airflow/models/taskinstance.py", line 1137, in _run_raw_task
    self._prepare_and_execute_task_with_callbacks(context, task)
  File "/home/airflow/sandbox/lib/python3.8/site-packages/airflow/models/taskinstance.py", line 1311, in _prepare_and_execute_task_with_callbacks
    result = self._execute_task(context, task_copy)
  File "/home/airflow/sandbox/lib/python3.8/site-packages/airflow/models/taskinstance.py", line 1341, in _execute_task
    result = task_copy.execute(context=context)
  File "/home/airflow/sandbox/lib/python3.8/site-packages/airflow/operators/python.py", line 150, in execute
    return_value = self.execute_callable()
  File "/home/airflow/sandbox/lib/python3.8/site-packages/airflow/operators/python.py", line 161, in execute_callable
    return self.python_callable(*self.op_args, **self.op_kwargs)
  File "/home/airflow/airflow/dags/open_aq.py", line 26, in _process_data
    print(data[0]['results'])
KeyError: 0
[2021-06-30 08:51:54,244] {taskinstance.py:1524} INFO - Marking task as FAILED. dag_id=open_aq, task_id=process_data, execution_date=20210629T170919, start_date=20210630T085153, end_date=20210630T085154
[2021-06-30 08:51:54,296] {local_task_job.py:151} INFO - Task exited with return code 1
