[2021-07-01 16:42:09,629] {taskinstance.py:876} INFO - Dependencies all met for <TaskInstance: get_data_patient.write_users 2021-07-01T16:42:03.454547+00:00 [queued]>
[2021-07-01 16:42:09,639] {taskinstance.py:876} INFO - Dependencies all met for <TaskInstance: get_data_patient.write_users 2021-07-01T16:42:03.454547+00:00 [queued]>
[2021-07-01 16:42:09,640] {taskinstance.py:1067} INFO - 
--------------------------------------------------------------------------------
[2021-07-01 16:42:09,640] {taskinstance.py:1068} INFO - Starting attempt 1 of 1
[2021-07-01 16:42:09,641] {taskinstance.py:1069} INFO - 
--------------------------------------------------------------------------------
[2021-07-01 16:42:09,658] {taskinstance.py:1087} INFO - Executing <Task(PythonOperator): write_users> on 2021-07-01T16:42:03.454547+00:00
[2021-07-01 16:42:09,662] {standard_task_runner.py:52} INFO - Started process 25811 to run task
[2021-07-01 16:42:09,666] {standard_task_runner.py:76} INFO - Running: ['airflow', 'tasks', 'run', 'get_data_patient', 'write_users', '2021-07-01T16:42:03.454547+00:00', '--job-id', '1007', '--pool', 'default_pool', '--raw', '--subdir', 'DAGS_FOLDER/get_Data_Patient.py', '--cfg-path', '/tmp/tmp4mayq9eg', '--error-file', '/tmp/tmpuiht8ej5']
[2021-07-01 16:42:09,667] {standard_task_runner.py:77} INFO - Job 1007: Subtask write_users
[2021-07-01 16:42:09,760] {logging_mixin.py:104} INFO - Running <TaskInstance: get_data_patient.write_users 2021-07-01T16:42:03.454547+00:00 [running]> on host airflowvm
[2021-07-01 16:42:09,865] {taskinstance.py:1280} INFO - Exporting the following env vars:
AIRFLOW_CTX_DAG_OWNER=airflow
AIRFLOW_CTX_DAG_ID=get_data_patient
AIRFLOW_CTX_TASK_ID=write_users
AIRFLOW_CTX_EXECUTION_DATE=2021-07-01T16:42:03.454547+00:00
AIRFLOW_CTX_DAG_RUN_ID=manual__2021-07-01T16:42:03.454547+00:00
[2021-07-01 16:42:09,879] {taskinstance.py:1481} ERROR - Task failed with exception
Traceback (most recent call last):
  File "/home/airflow/sandbox/lib/python3.8/site-packages/airflow/models/taskinstance.py", line 1137, in _run_raw_task
    self._prepare_and_execute_task_with_callbacks(context, task)
  File "/home/airflow/sandbox/lib/python3.8/site-packages/airflow/models/taskinstance.py", line 1311, in _prepare_and_execute_task_with_callbacks
    result = self._execute_task(context, task_copy)
  File "/home/airflow/sandbox/lib/python3.8/site-packages/airflow/models/taskinstance.py", line 1341, in _execute_task
    result = task_copy.execute(context=context)
  File "/home/airflow/sandbox/lib/python3.8/site-packages/airflow/operators/python.py", line 150, in execute
    return_value = self.execute_callable()
  File "/home/airflow/sandbox/lib/python3.8/site-packages/airflow/operators/python.py", line 161, in execute_callable
    return self.python_callable(*self.op_args, **self.op_kwargs)
  File "/home/airflow/airflow/dags/get_Data_Patient.py", line 50, in _write_users
    df = read_json(users)
  File "/home/airflow/sandbox/lib/python3.8/site-packages/pandas/util/_decorators.py", line 199, in wrapper
    return func(*args, **kwargs)
  File "/home/airflow/sandbox/lib/python3.8/site-packages/pandas/util/_decorators.py", line 299, in wrapper
    return func(*args, **kwargs)
  File "/home/airflow/sandbox/lib/python3.8/site-packages/pandas/io/json/_json.py", line 540, in read_json
    json_reader = JsonReader(
  File "/home/airflow/sandbox/lib/python3.8/site-packages/pandas/io/json/_json.py", line 622, in __init__
    data = self._get_data_from_filepath(filepath_or_buffer)
  File "/home/airflow/sandbox/lib/python3.8/site-packages/pandas/io/json/_json.py", line 659, in _get_data_from_filepath
    self.handles = get_handle(
  File "/home/airflow/sandbox/lib/python3.8/site-packages/pandas/io/common.py", line 558, in get_handle
    ioargs = _get_filepath_or_buffer(
  File "/home/airflow/sandbox/lib/python3.8/site-packages/pandas/io/common.py", line 371, in _get_filepath_or_buffer
    raise ValueError(msg)
ValueError: Invalid file path or buffer object type: <class 'list'>
[2021-07-01 16:42:09,891] {taskinstance.py:1524} INFO - Marking task as FAILED. dag_id=get_data_patient, task_id=write_users, execution_date=20210701T164203, start_date=20210701T164209, end_date=20210701T164209
[2021-07-01 16:42:09,929] {local_task_job.py:151} INFO - Task exited with return code 1
