[2021-07-01 16:46:07,742] {taskinstance.py:876} INFO - Dependencies all met for <TaskInstance: get_data_patient.write_users 2021-07-01T16:42:03.454547+00:00 [queued]>
[2021-07-01 16:46:07,754] {taskinstance.py:876} INFO - Dependencies all met for <TaskInstance: get_data_patient.write_users 2021-07-01T16:42:03.454547+00:00 [queued]>
[2021-07-01 16:46:07,755] {taskinstance.py:1067} INFO - 
--------------------------------------------------------------------------------
[2021-07-01 16:46:07,755] {taskinstance.py:1068} INFO - Starting attempt 6 of 6
[2021-07-01 16:46:07,756] {taskinstance.py:1069} INFO - 
--------------------------------------------------------------------------------
[2021-07-01 16:46:07,778] {taskinstance.py:1087} INFO - Executing <Task(PythonOperator): write_users> on 2021-07-01T16:42:03.454547+00:00
[2021-07-01 16:46:07,782] {standard_task_runner.py:52} INFO - Started process 26453 to run task
[2021-07-01 16:46:07,788] {standard_task_runner.py:76} INFO - Running: ['airflow', 'tasks', 'run', 'get_data_patient', 'write_users', '2021-07-01T16:42:03.454547+00:00', '--job-id', '1014', '--pool', 'default_pool', '--raw', '--subdir', 'DAGS_FOLDER/get_Data_Patient.py', '--cfg-path', '/tmp/tmp2l6sx_n8', '--error-file', '/tmp/tmp63v3z5v3']
[2021-07-01 16:46:07,789] {standard_task_runner.py:77} INFO - Job 1014: Subtask write_users
[2021-07-01 16:46:07,917] {logging_mixin.py:104} INFO - Running <TaskInstance: get_data_patient.write_users 2021-07-01T16:42:03.454547+00:00 [running]> on host airflowvm
[2021-07-01 16:46:08,036] {taskinstance.py:1280} INFO - Exporting the following env vars:
AIRFLOW_CTX_DAG_OWNER=airflow
AIRFLOW_CTX_DAG_ID=get_data_patient
AIRFLOW_CTX_TASK_ID=write_users
AIRFLOW_CTX_EXECUTION_DATE=2021-07-01T16:42:03.454547+00:00
AIRFLOW_CTX_DAG_RUN_ID=manual__2021-07-01T16:42:03.454547+00:00
[2021-07-01 16:46:08,053] {logging_mixin.py:104} INFO - Users: [" [{'id': 4718, 'uid': '404d86a4-6138-4d86-87ed-5efbc2561cf9', 'medical_history': {}, 'user_id': '502c3cfb-2b79-4131-ad46-722e2d470a3b', 'birthdate': '1930-08-01', 'sex': 'M', 'created_at': '2021-03-30T09:50:38.662702+00:00', 'deleted_at': None, 'updated_at': '2021-04-12T16:55:42.865377+00:00', 'is_test': False}, {'id': 4727, 'uid': '57fc6ce3-5c5f-4811-b978-e58782716cda', 'medical_history': {}, 'user_id': '6a202726-9d80-46ac-9ff0-edd0940ea479', 'birthdate': '1947-03-15', 'sex': 'F', 'created_at': '2021-03-30T18:14:20.305891+00:00', 'deleted_at': None, 'updated_at': '2021-04-12T16:55:42.86945+00:00', 'is_test': False}]"]
[2021-07-01 16:46:08,054] {taskinstance.py:1481} ERROR - Task failed with exception
Traceback (most recent call last):
  File "/home/airflow/sandbox/lib/python3.8/site-packages/airflow/models/taskinstance.py", line 1137, in _run_raw_task
    self._prepare_and_execute_task_with_callbacks(context, task)
  File "/home/airflow/sandbox/lib/python3.8/site-packages/airflow/models/taskinstance.py", line 1311, in _prepare_and_execute_task_with_callbacks
    result = self._execute_task(context, task_copy)
  File "/home/airflow/sandbox/lib/python3.8/site-packages/airflow/models/taskinstance.py", line 1341, in _execute_task
    result = task_copy.execute(context=context)
  File "/home/airflow/sandbox/lib/python3.8/site-packages/airflow/operators/python.py", line 150, in execute
    return_value = self.execute_callable()
  File "/home/airflow/sandbox/lib/python3.8/site-packages/airflow/operators/python.py", line 161, in execute_callable
    return self.python_callable(*self.op_args, **self.op_kwargs)
  File "/home/airflow/airflow/dags/get_Data_Patient.py", line 51, in _write_users
    users = json.loads(users[0])
  File "/usr/lib/python3.8/json/__init__.py", line 357, in loads
    return _default_decoder.decode(s)
  File "/usr/lib/python3.8/json/decoder.py", line 337, in decode
    obj, end = self.raw_decode(s, idx=_w(s, 0).end())
  File "/usr/lib/python3.8/json/decoder.py", line 353, in raw_decode
    obj, end = self.scan_once(s, idx)
json.decoder.JSONDecodeError: Expecting property name enclosed in double quotes: line 1 column 4 (char 3)
[2021-07-01 16:46:08,057] {taskinstance.py:1524} INFO - Marking task as FAILED. dag_id=get_data_patient, task_id=write_users, execution_date=20210701T164203, start_date=20210701T164607, end_date=20210701T164608
[2021-07-01 16:46:08,131] {local_task_job.py:151} INFO - Task exited with return code 1
