[2021-06-29 16:38:48,671] {taskinstance.py:876} INFO - Dependencies all met for <TaskInstance: open_aq.store_data 2021-06-29T16:38:33.458784+00:00 [queued]>
[2021-06-29 16:38:48,693] {taskinstance.py:876} INFO - Dependencies all met for <TaskInstance: open_aq.store_data 2021-06-29T16:38:33.458784+00:00 [queued]>
[2021-06-29 16:38:48,693] {taskinstance.py:1067} INFO - 
--------------------------------------------------------------------------------
[2021-06-29 16:38:48,693] {taskinstance.py:1068} INFO - Starting attempt 1 of 1
[2021-06-29 16:38:48,694] {taskinstance.py:1069} INFO - 
--------------------------------------------------------------------------------
[2021-06-29 16:38:48,710] {taskinstance.py:1087} INFO - Executing <Task(BashOperator): store_data> on 2021-06-29T16:38:33.458784+00:00
[2021-06-29 16:38:48,719] {standard_task_runner.py:52} INFO - Started process 36647 to run task
[2021-06-29 16:38:48,727] {standard_task_runner.py:76} INFO - Running: ['airflow', 'tasks', 'run', 'open_aq', 'store_data', '2021-06-29T16:38:33.458784+00:00', '--job-id', '679', '--pool', 'default_pool', '--raw', '--subdir', 'DAGS_FOLDER/open_aq.py', '--cfg-path', '/tmp/tmpt1krlbre', '--error-file', '/tmp/tmpqbdmj_a3']
[2021-06-29 16:38:48,730] {standard_task_runner.py:77} INFO - Job 679: Subtask store_data
[2021-06-29 16:38:48,816] {logging_mixin.py:104} INFO - Running <TaskInstance: open_aq.store_data 2021-06-29T16:38:33.458784+00:00 [running]> on host airflowvm
[2021-06-29 16:38:48,938] {taskinstance.py:1280} INFO - Exporting the following env vars:
AIRFLOW_CTX_DAG_OWNER=airflow
AIRFLOW_CTX_DAG_ID=open_aq
AIRFLOW_CTX_TASK_ID=store_data
AIRFLOW_CTX_EXECUTION_DATE=2021-06-29T16:38:33.458784+00:00
AIRFLOW_CTX_DAG_RUN_ID=manual__2021-06-29T16:38:33.458784+00:00
[2021-06-29 16:38:48,939] {subprocess.py:52} INFO - Tmp dir root location: 
 /tmp
[2021-06-29 16:38:48,940] {subprocess.py:63} INFO - Running command: ['bash', '-c', 'echo -e ".separator ";"\n.import /tmp/processed_data.csv users" \n                              | psql /home/airflow/airflow/airflow.db']
[2021-06-29 16:38:48,950] {subprocess.py:75} INFO - Output:
[2021-06-29 16:38:48,952] {subprocess.py:79} INFO - .separator
[2021-06-29 16:38:48,953] {subprocess.py:79} INFO - bash: line 1:
[2021-06-29 16:38:48,953] {subprocess.py:79} INFO - .import /tmp/processed_data.csv users: No such file or directory
[2021-06-29 16:38:48,953] {subprocess.py:79} INFO - bash: -c: line 2: syntax error near unexpected token `|'
[2021-06-29 16:38:48,954] {subprocess.py:79} INFO - bash: -c: line 2: `                              | psql /home/airflow/airflow/airflow.db'
[2021-06-29 16:38:48,954] {subprocess.py:83} INFO - Command exited with return code 1
[2021-06-29 16:38:48,973] {taskinstance.py:1481} ERROR - Task failed with exception
Traceback (most recent call last):
  File "/home/airflow/sandbox/lib/python3.8/site-packages/airflow/models/taskinstance.py", line 1137, in _run_raw_task
    self._prepare_and_execute_task_with_callbacks(context, task)
  File "/home/airflow/sandbox/lib/python3.8/site-packages/airflow/models/taskinstance.py", line 1311, in _prepare_and_execute_task_with_callbacks
    result = self._execute_task(context, task_copy)
  File "/home/airflow/sandbox/lib/python3.8/site-packages/airflow/models/taskinstance.py", line 1341, in _execute_task
    result = task_copy.execute(context=context)
  File "/home/airflow/sandbox/lib/python3.8/site-packages/airflow/operators/bash.py", line 180, in execute
    raise AirflowException('Bash command failed. The command returned a non-zero exit code.')
airflow.exceptions.AirflowException: Bash command failed. The command returned a non-zero exit code.
[2021-06-29 16:38:48,976] {taskinstance.py:1524} INFO - Marking task as FAILED. dag_id=open_aq, task_id=store_data, execution_date=20210629T163833, start_date=20210629T163848, end_date=20210629T163848
[2021-06-29 16:38:49,024] {local_task_job.py:151} INFO - Task exited with return code 1
