[2021-06-29 16:44:04,571] {taskinstance.py:876} INFO - Dependencies all met for <TaskInstance: open_aq.store_data 2021-06-29T16:38:33.458784+00:00 [queued]>
[2021-06-29 16:44:04,596] {taskinstance.py:876} INFO - Dependencies all met for <TaskInstance: open_aq.store_data 2021-06-29T16:38:33.458784+00:00 [queued]>
[2021-06-29 16:44:04,597] {taskinstance.py:1067} INFO - 
--------------------------------------------------------------------------------
[2021-06-29 16:44:04,598] {taskinstance.py:1068} INFO - Starting attempt 4 of 4
[2021-06-29 16:44:04,598] {taskinstance.py:1069} INFO - 
--------------------------------------------------------------------------------
[2021-06-29 16:44:04,615] {taskinstance.py:1087} INFO - Executing <Task(BashOperator): store_data> on 2021-06-29T16:38:33.458784+00:00
[2021-06-29 16:44:04,621] {standard_task_runner.py:52} INFO - Started process 37213 to run task
[2021-06-29 16:44:04,630] {standard_task_runner.py:76} INFO - Running: ['airflow', 'tasks', 'run', 'open_aq', 'store_data', '2021-06-29T16:38:33.458784+00:00', '--job-id', '682', '--pool', 'default_pool', '--raw', '--subdir', 'DAGS_FOLDER/open_aq.py', '--cfg-path', '/tmp/tmpuzkuoqhp', '--error-file', '/tmp/tmpfggtw2q0']
[2021-06-29 16:44:04,631] {standard_task_runner.py:77} INFO - Job 682: Subtask store_data
[2021-06-29 16:44:04,725] {logging_mixin.py:104} INFO - Running <TaskInstance: open_aq.store_data 2021-06-29T16:38:33.458784+00:00 [running]> on host airflowvm
[2021-06-29 16:44:04,858] {taskinstance.py:1280} INFO - Exporting the following env vars:
AIRFLOW_CTX_DAG_OWNER=airflow
AIRFLOW_CTX_DAG_ID=open_aq
AIRFLOW_CTX_TASK_ID=store_data
AIRFLOW_CTX_EXECUTION_DATE=2021-06-29T16:38:33.458784+00:00
AIRFLOW_CTX_DAG_RUN_ID=manual__2021-06-29T16:38:33.458784+00:00
[2021-06-29 16:44:04,859] {subprocess.py:52} INFO - Tmp dir root location: 
 /tmp
[2021-06-29 16:44:04,860] {subprocess.py:63} INFO - Running command: ['bash', '-c', 'psql -d *** -U *** -c "\\copy usa from /tmp/processed_data.csv delimiter \';\' csv header;""']
[2021-06-29 16:44:04,869] {subprocess.py:75} INFO - Output:
[2021-06-29 16:44:04,871] {subprocess.py:79} INFO - bash: -c: line 0: unexpected EOF while looking for matching `"'
[2021-06-29 16:44:04,871] {subprocess.py:79} INFO - bash: -c: line 1: syntax error: unexpected end of file
[2021-06-29 16:44:04,872] {subprocess.py:83} INFO - Command exited with return code 1
[2021-06-29 16:44:04,893] {taskinstance.py:1481} ERROR - Task failed with exception
Traceback (most recent call last):
  File "/home/airflow/sandbox/lib/python3.8/site-packages/airflow/models/taskinstance.py", line 1137, in _run_raw_task
    self._prepare_and_execute_task_with_callbacks(context, task)
  File "/home/airflow/sandbox/lib/python3.8/site-packages/airflow/models/taskinstance.py", line 1311, in _prepare_and_execute_task_with_callbacks
    result = self._execute_task(context, task_copy)
  File "/home/airflow/sandbox/lib/python3.8/site-packages/airflow/models/taskinstance.py", line 1341, in _execute_task
    result = task_copy.execute(context=context)
  File "/home/airflow/sandbox/lib/python3.8/site-packages/airflow/operators/bash.py", line 180, in execute
    raise AirflowException('Bash command failed. The command returned a non-zero exit code.')
airflow.exceptions.AirflowException: Bash command failed. The command returned a non-zero exit code.
[2021-06-29 16:44:04,896] {taskinstance.py:1524} INFO - Marking task as FAILED. dag_id=open_aq, task_id=store_data, execution_date=20210629T163833, start_date=20210629T164404, end_date=20210629T164404
[2021-06-29 16:44:04,967] {local_task_job.py:151} INFO - Task exited with return code 1
