[2021-07-01 08:50:42,859] {taskinstance.py:876} INFO - Dependencies all met for <TaskInstance: user_processing_v2.store_data 2021-06-30T14:29:12.044488+00:00 [queued]>
[2021-07-01 08:50:42,886] {taskinstance.py:876} INFO - Dependencies all met for <TaskInstance: user_processing_v2.store_data 2021-06-30T14:29:12.044488+00:00 [queued]>
[2021-07-01 08:50:42,887] {taskinstance.py:1067} INFO - 
--------------------------------------------------------------------------------
[2021-07-01 08:50:42,888] {taskinstance.py:1068} INFO - Starting attempt 12 of 12
[2021-07-01 08:50:42,889] {taskinstance.py:1069} INFO - 
--------------------------------------------------------------------------------
[2021-07-01 08:50:42,901] {taskinstance.py:1087} INFO - Executing <Task(PythonOperator): store_data> on 2021-06-30T14:29:12.044488+00:00
[2021-07-01 08:50:42,909] {standard_task_runner.py:52} INFO - Started process 34401 to run task
[2021-07-01 08:50:42,921] {standard_task_runner.py:76} INFO - Running: ['airflow', 'tasks', 'run', 'user_processing_v2', 'store_data', '2021-06-30T14:29:12.044488+00:00', '--job-id', '934', '--pool', 'default_pool', '--raw', '--subdir', 'DAGS_FOLDER/user_processing_v2.py', '--cfg-path', '/tmp/tmpookn4jx9', '--error-file', '/tmp/tmp9327wo5d']
[2021-07-01 08:50:42,923] {standard_task_runner.py:77} INFO - Job 934: Subtask store_data
[2021-07-01 08:50:43,036] {logging_mixin.py:104} INFO - Running <TaskInstance: user_processing_v2.store_data 2021-06-30T14:29:12.044488+00:00 [running]> on host airflowvm
[2021-07-01 08:50:43,171] {taskinstance.py:1280} INFO - Exporting the following env vars:
AIRFLOW_CTX_DAG_OWNER=airflow
AIRFLOW_CTX_DAG_ID=user_processing_v2
AIRFLOW_CTX_TASK_ID=store_data
AIRFLOW_CTX_EXECUTION_DATE=2021-06-30T14:29:12.044488+00:00
AIRFLOW_CTX_DAG_RUN_ID=manual__2021-06-30T14:29:12.044488+00:00
[2021-07-01 08:50:43,191] {taskinstance.py:1481} ERROR - Task failed with exception
Traceback (most recent call last):
  File "/home/airflow/sandbox/lib/python3.8/site-packages/airflow/models/taskinstance.py", line 1137, in _run_raw_task
    self._prepare_and_execute_task_with_callbacks(context, task)
  File "/home/airflow/sandbox/lib/python3.8/site-packages/airflow/models/taskinstance.py", line 1311, in _prepare_and_execute_task_with_callbacks
    result = self._execute_task(context, task_copy)
  File "/home/airflow/sandbox/lib/python3.8/site-packages/airflow/models/taskinstance.py", line 1341, in _execute_task
    result = task_copy.execute(context=context)
  File "/home/airflow/sandbox/lib/python3.8/site-packages/airflow/operators/python.py", line 150, in execute
    return_value = self.execute_callable()
  File "/home/airflow/sandbox/lib/python3.8/site-packages/airflow/operators/python.py", line 161, in execute_callable
    return self.python_callable(*self.op_args, **self.op_kwargs)
  File "/home/airflow/airflow/dags/user_processing_v2.py", line 39, in _storing
    processing_user = json.loads(processing_user)
  File "/usr/lib/python3.8/json/__init__.py", line 341, in loads
    raise TypeError(f'the JSON object must be str, bytes or bytearray, '
TypeError: the JSON object must be str, bytes or bytearray, not list
[2021-07-01 08:50:43,339] {taskinstance.py:1524} INFO - Marking task as FAILED. dag_id=user_processing_v2, task_id=store_data, execution_date=20210630T142912, start_date=20210701T085042, end_date=20210701T085043
[2021-07-01 08:50:43,588] {local_task_job.py:151} INFO - Task exited with return code 1
